Workbook

Sheet Auteur
C1: Saison #25 - Troisième série de Questionnaires
B2: Numéro de Questionnaire
B3: Date de création :
B4: Auteur(s) :
B5: Équipe de(s) l’auteur(s) :
B6: Date des parties :
B7: Partie 1
B8: Partie 2
C10: Série 1 | D10: Langue
C11: Individuelle
C12: Rédiger 8 questions de niveaux faciles et constants.
B13: Équipe A
A14: 1 | B14: 1
A15: 1 | B15: 2
A16: 1 | B16: 3
A17: 1 | B17: 4
B18: Équipe B
A19: 1 | B19: 5
A20: 1 | B20: 6
A21: 1 | B21: 7
A22: 1 | B22: 8
C24: Série 2 | D24: Géographie
C25: Collective
C26: Les 5 questions doivent couvrir l'ensemble du thème. Varier les sujets, formulations, longueurs, difficultés, etc.
A27: 1 à 3 | B27: 1
A28: 1 à 3 | B28: 2
A29: 1 à 3 | B29: 3
A30: 1 à 3 | B30: 4
A31: 1 à 3 | B31: 5
C33: Série 3 | D33: Arts et médias
C34: Collective
C35: Les 5 questions doivent couvrir l'ensemble des thèmes. Varier les sujets, formulations, longueurs, difficultés, etc.
A36: 1 à 3 | B36: 1
A37: 1 à 3 | B37: 2
A38: 1 à 3 | B38: 3
A39: 1 à 3 | B39: 4
A40: 1 à 3 | B40: 5
C42: Série 4 | D42: Histoire et société
C43: Collective
C44: Au moins 2 questions dans chacun des thèmes.
...

Sheet Vers BD
A1: tblThèmes
A2: NoQuestionnaire | B2: NoSérie | C2: Thème | D2: SousThème
A3: =Auteur!$D$2 -> 0 | B3: 1 | C3: =INDIRECT(Adresses!C9) -> Langue | D3: =IF(INDIRECT(Adresses!E9)<>0,INDIRECT(Adresses!E9),"")
A4: =Auteur!$D$2 -> 0 | B4: =B3+1 -> 2 | C4: =INDIRECT(Adresses!C17) -> Géographie | D4: =IF(INDIRECT(Adresses!E17)<>0,INDIRECT(Adresses!E17),"")
A5: =Auteur!$D$2 -> 0 | B5: =B4+1 -> 3 | C5: =INDIRECT(Adresses!C22) -> Arts et médias | D5: =IF(INDIRECT(Adresses!E22)<>0,INDIRECT(Adresses!E22),"")
A6: =Auteur!$D$2 -> 0 | B6: =B5+1 -> 4 | C6: =INDIRECT(Adresses!C27) -> Histoire et société | D6: =IF(INDIRECT(Adresses!E27)<>0,INDIRECT(Adresses!E27),"")
A7: =Auteur!$D$2 -> 0 | B7: =B6+1 -> 5 | C7: =INDIRECT(Adresses!C32) -> Une année, décennie ou siècle | D7: =IF(INDIRECT(Adresses!E32)<>0,INDIRECT(Adresses!E32),"")
A8: =Auteur!$D$2 -> 0 | B8: =B7+1 -> 6 | C8: =INDIRECT(Adresses!C37) -> -- Choisir un thème -- | D8: =IF(INDIRECT(Adresses!E37)<>0,INDIRECT(Adresses!E37),"")
A9: =Auteur!$D$2 -> 0 | B9: =B8+1 -> 7 | C9: =INDIRECT(Adresses!C45) -> Langues et littérature | D9: =IF(INDIRECT(Adresses!E45)<>0,INDIRECT(Adresses!E45),"")
A10: =Auteur!$D$2 -> 0 | B10: =B9+1 -> 8 | C10: =INDIRECT(Adresses!C50) -> Sports et loisirs | D10: =IF(INDIRECT(Adresses!E50)<>0,INDIRECT(Adresses!E50),"")
A11: =Auteur!$D$2 -> 0 | B11: =B10+1 -> 9 | C11: =INDIRECT(Adresses!C55) -> -- Choisir un thème -- | D11: =IF(INDIRECT(Adresses!E17)<>0,INDIRECT(Adresses!E17),"")
A12: =Auteur!$D$2 -> 0 | B12: =B11+1 -> 10 | C12: =INDIRECT(Adresses!C58) -> -- Choisir un thème -- | D12: =IF(INDIRECT(Adresses!E58)<>0,INDIRECT(Adresses!E58),"")
A13: =Auteur!$D$2 -> 0 | B13: =B12+1 -> 11 | C13: =INDIRECT(Adresses!C62) -> Musique | D13: =IF(INDIRECT(Adresses!E62)<>0,INDIRECT(Adresses!E62),"")
A14: =Auteur!$D$2 -> 0 | B14: =B13+1 -> 12 | C14: =INDIRECT(Adresses!C67) -> Sciences | D14: =IF(INDIRECT(Adresses!E67)<>0,INDIRECT(Adresses!E67),"")
A15: =Auteur!$D$2 -> 0 | B15: =B14+1 -> 13 | C15: =INDIRECT(Adresses!C72) -> Libre | D15: =IF(INDIRECT(Adresses!E72)<>0,INDIRECT(Adresses!E72),"") -> Saisir sous-thème 1 ici / Saisir sous-thème 2 ici
A16: =Auteur!$D$2 -> 0 | B16: =B15+1 -> 14 | C16: =INDIRECT(Adresses!C80) -> Divers | D16: =IF(INDIRECT(Adresses!E80)<>0,INDIRECT(Adresses!E80),"")
A17: =Auteur!$D$2 -> 0 | B17: =B16+1 -> 15 | C17: =INDIRECT(Adresses!C90) -> Actualité | D17: =IF(INDIRECT(Adresses!E90)<>0,INDIRECT(Adresses!E90),"")
A18: =Auteur!$D$2 -> 0 | B18: =B17+1 -> 16 | C18: =INDIRECT(Adresses!C91) -> Divers | D18: =IF(INDIRECT(Adresses!E91)<>0,INDIRECT(Adresses!E91),"")
A20: tblQuestionnaires
A21: NoQuestionnaire | B21: NoSérie | C21: NoQuestion | D21: TexteQuestion | E21: Réponse
A22: =Auteur!$D$2 -> 0 | B22: 1 | C22: =Auteur!B14 -> 1 | D22: =INDIRECT(Adresses!G9) -> 0 | E22: =INDIRECT(Adresses!H9) -> 0
A23: =Auteur!$D$2 -> 0 | B23: 1 | C23: =Auteur!B15 -> 2 | D23: =INDIRECT(Adresses!G10) -> 0 | E23: =INDIRECT(Adresses!H10) -> 0
A24: =Auteur!$D$2 -> 0 | B24: 1 | C24: =Auteur!B16 -> 3 | D24: =INDIRECT(Adresses!G11) -> 0 | E24: =INDIRECT(Adresses!H11) -> 0
A25: =Auteur!$D$2 -> 0 | B25: 1 | C25: =Auteur!B17 -> 4 | D25: =INDIRECT(Adresses!G12) -> 0 | E25: =INDIRECT(Adresses!H12) -> 0
A26: =Auteur!$D$2 -> 0 | B26: 1 | C26: =Auteur!B19 -> 5 | D26: =INDIRECT(Adresses!G13) -> 0 | E26: =INDIRECT(Adresses!H13) -> 0
A27: =Auteur!$D$2 -> 0 | B27: 1 | C27: =Auteur!B20 -> 6 | D27: =INDIRECT(Adresses!G14) -> 0 | E27: =INDIRECT(Adresses!H14) -> 0
A28: =Auteur!$D$2 -> 0 | B28: 1 | C28: =Auteur!B21 -> 7 | D28: =INDIRECT(Adresses!G15) -> 0 | E28: =INDIRECT(Adresses!H15) -> 0
A29: =Auteur!$D$2 -> 0 | B29: 1 | C29: =Auteur!B22 -> 8 | D29: =INDIRECT(Adresses!G16) -> 0 | E29: =INDIRECT(Adresses!H16) -> 0
A30: =Auteur!$D$2 -> 0 | B30: 2 | C30: =Auteur!B27 -> 1 | D30: =INDIRECT(Adresses!G17) -> 0 | E30: =INDIRECT(Adresses!H17) -> 0
A31: =Auteur!$D$2 -> 0 | B31: 2 | C31: =Auteur!B28 -> 2 | D31: =INDIRECT(Adresses!G18) -> 0 | E31: =INDIRECT(Adresses!H18) -> 0
A32: =Auteur!$D$2 -> 0 | B32: 2 | C32: =Auteur!B29 -> 3 | D32: =INDIRECT(Adresses!G19) -> 0 | E32: =INDIRECT(Adresses!H19) -> 0
A33: =Auteur!$D$2 -> 0 | B33: 2 | C33: =Auteur!B30 -> 4 | D33: =INDIRECT(Adresses!G20) -> 0 | E33: =INDIRECT(Adresses!H20) -> 0
A34: =Auteur!$D$2 -> 0 | B34: 2 | C34: =Auteur!B31 -> 5 | D34: =INDIRECT(Adresses!G21) -> 0 | E34: =INDIRECT(Adresses!H21) -> 0
A35: =Auteur!$D$2 -> 0 | B35: 3 | C35: =Auteur!B36 -> 1 | D35: =INDIRECT(Adresses!G22) -> 0 | E35: =INDIRECT(Adresses!H22) -> 0
A36: =Auteur!$D$2 -> 0 | B36: 3 | C36: =Auteur!B37 -> 2 | D36: =INDIRECT(Adresses!G23) -> 0 | E36: =INDIRECT(Adresses!H23) -> 0
A37: =Auteur!$D$2 -> 0 | B37: 3 | C37: =Auteur!B38 -> 3 | D37: =INDIRECT(Adresses!G24) -> 0 | E37: =INDIRECT(Adresses!H24) -> 0
A38: =Auteur!$D$2 -> 0 | B38: 3 | C38: =Auteur!B39 -> 4 | D38: =INDIRECT(Adresses!G25) -> 0 | E38: =INDIRECT(Adresses!H25) -> 0
A39: =Auteur!$D$2 -> 0 | B39: 3 | C39: =Auteur!B40 -> 5 | D39: =INDIRECT(Adresses!G26) -> 0 | E39: =INDIRECT(Adresses!H26) -> 0
A40: =Auteur!$D$2 -> 0 | B40: 4 | C40: =Auteur!B45 -> 1 | D40: =INDIRECT(Adresses!G27) -> 0 | E40: =INDIRECT(Adresses!H27) -> 0
A41: =Auteur!$D$2 -> 0 | B41: 4 | C41: =Auteur!B46 -> 2 | D41: =INDIRECT(Adresses!G28) -> 0 | E41: =INDIRECT(Adresses!H28) -> 0
...

Sheet De BD à Auteur
A2: Numéro de Questionnaire | C2: 3 | G2: Géographie
A3: Date de création : | C3: 28 mars 2003 | G3: Société
A4: Auteur(s) : | C4: Martin Sirois | G4: Actualité
A5: Équipe de(s) l’auteur(s) : | C5: Les Incultophobes
A6: Date de la partie :
A7: Équipe A :
A8: Équipe B :
A10: Section A : 1ère individuelle
A12: Série #1 – Individuelle | C12: Thème
A13: Individuelle | C13: Sous-thème | D13: Capitale
A14: Équipe A
A17: 1 | B17: ='Vers BD'!D23 -> 0 | D17: ='Vers BD'!E23 -> 0
A18: 2 | B18: Quelle est la capitale de la Bulgarie? | D18: Sofia
A19: 3 | B19: Quelle est la capitale de l'Alberta? | D19: Edmonton
A20: 4 | B20: Quelle est la capitale de la crevette au Québec? | D20: Matane
A21: Équipe B
A22: 1 | B22: Quelle est la capitale du "poisson des chenaux" au Québec? | D22: Ste-Anne de la Pérade
A23: 2 | B23: Quelle est la capitale de la Colombie-Britannique? | D23: Victoria
A24: 3 | B24: Quelle est la capitale du Mexique? | D24: Mexico
A25: 4 | B25: Quelle est la capitale du Portugal? | D25: Lisbonne
A27: Section B : 1ère collective
A29: Série #2 – Collective | C29: Thème | D29: Cinéma
A30: Réplique : OUI, consultation : NON
A31: 1 | B31: Harrison Ford est un archéologue dans ce film de 1981? | D31: Les aventuriers de l’arche perdue
A32: 2 | B32: Elle devint populaire grâce au rôle de Marry Poppins? | D32: Julie Andrews
A33: 3 | B33: Dans ce film, Marty voyage dans le temps et rencontre son père et sa mère adolescents ? | D33: Back to the future (Retour vers le futur) accepter back to the future I
A34: 4 | B34: De quel film de 1984 est tiré la célèbre phrase « La guerre, la guerre, c'est pas une raison pour se faire mal »? | D34: La Guerre Des Tuques
A35: 5 | B35: Quel est le prénom de le petite sirène de Disney? | D35: Ariel
A37: Série #3 – Collective | C37: Thème | D37: Histoire générale
A38: Réplique : OUI, consultation : NON
A39: 1 | B39: Grande période de la préhistoire durant laquelle, l'homme découvrit l'usage du feu et inventa le langage? | D39: Le paléolithique
A40: 2 | B40: Quel et le nom du chef des Gaulois qui tenta vainement de résister à l'invasion romaine au 1er siècle avant Jésus-Christ ? | D40: Vercingetorix
A41: 3 | B41: À quel siècle Marco Polo entreprit-il son voyage en Asie ? | D41: 13ième siècle
A42: 4 | B42: Quel prix Martin Luther King reçut-il, 4 ans avant de se faire assassiner, à Memphis en 1968? | D42: Prix Nobel de la paix
A43: 5 | B43: De quel traité est tiré cet extrait ? | D43: Le traité de Paris
B44: "…De plus, Sa Majesté Trés Chretienne cede & garantit à Sa dite Majesté Britannique, en toute Proprieté, le Canada avec toutes ses Dependances, ainsi que l'Isle du Cap Breton, & toutes les autres Isles, & Côtes, dans le Golphe & Fleuve S' Laurent, & gener

Sheet Adresses
A1: Liste des références pour la construction des formules
B2: Nom feuille | C2: Auteur
B3: Colonne Thème | C3: D
B4: Colonne sous-Thème | C4: D
B5: Colonne Question | C5: C
B6: colonne réponse | C6: D
A8: Série | B8: Rangée Thèmes | C8: Adresse Thèmes | D8: Rangée Sous-Thèmes | E8: Adresse Sous-Thèmes | F8: Rangée Q1 | G8: Adresse Question 1 | H8: Adresse réponse 1
A9: 1 | B9: 10 | C9: =$C$2&"!"&$C$3&B9 -> Auteur!D10 | D9: =B9+1 -> 11 | E9: =$C$2&"!"&$C$3&D9 -> Auteur!D11 | F9: 14 | G9: =$C$2&"!"&$C$5&F9 -> Auteur!C14 | H9: =$C$2&"!"&$C$6&F9 -> Auteur!D14
A10: 1 | F10: =+F9+1 -> 15 | G10: =$C$2&"!"&$C$5&F10 -> Auteur!C15 | H10: =$C$2&"!"&$C$6&F10 -> Auteur!D15
A11: 1 | F11: =+F10+1 -> 16 | G11: =$C$2&"!"&$C$5&F11 -> Auteur!C16 | H11: =$C$2&"!"&$C$6&F11 -> Auteur!D16
A12: 1 | F12: =+F11+1 -> 17 | G12: =$C$2&"!"&$C$5&F12 -> Auteur!C17 | H12: =$C$2&"!"&$C$6&F12 -> Auteur!D17
A13: 1 | F13: 19 | G13: =$C$2&"!"&$C$5&F13 -> Auteur!C19 | H13: =$C$2&"!"&$C$6&F13 -> Auteur!D19
A14: 1 | F14: =+F13+1 -> 20 | G14: =$C$2&"!"&$C$5&F14 -> Auteur!C20 | H14: =$C$2&"!"&$C$6&F14 -> Auteur!D20
A15: 1 | F15: =+F14+1 -> 21 | G15: =$C$2&"!"&$C$5&F15 -> Auteur!C21 | H15: =$C$2&"!"&$C$6&F15 -> Auteur!D21
A16: 1 | F16: =+F15+1 -> 22 | G16: =$C$2&"!"&$C$5&F16 -> Auteur!C22 | H16: =$C$2&"!"&$C$6&F16 -> Auteur!D22
A17: =A9+1 -> 2 | B17: 24 | C17: =$C$2&"!"&$C$3&B17 -> Auteur!D24 | D17: =B17+1 -> 25 | E17: =$C$2&"!"&$C$3&D17 -> Auteur!D25 | F17: 27 | G17: =$C$2&"!"&$C$5&F17 -> Auteur!C27 | H17: =$C$2&"!"&$C$6&F17 -> Auteur!D27
A18: 2 | F18: =+F17+1 -> 28 | G18: =$C$2&"!"&$C$5&F18 -> Auteur!C28 | H18: =$C$2&"!"&$C$6&F18 -> Auteur!D28
A19: 2 | F19: =+F18+1 -> 29 | G19: =$C$2&"!"&$C$5&F19 -> Auteur!C29 | H19: =$C$2&"!"&$C$6&F19 -> Auteur!D29
A20: 2 | F20: =+F19+1 -> 30 | G20: =$C$2&"!"&$C$5&F20 -> Auteur!C30 | H20: =$C$2&"!"&$C$6&F20 -> Auteur!D30
A21: 2 | F21: =+F20+1 -> 31 | G21: =$C$2&"!"&$C$5&F21 -> Auteur!C31 | H21: =$C$2&"!"&$C$6&F21 -> Auteur!D31
A22: =A17+1 -> 3 | B22: 33 | C22: =$C$2&"!"&$C$3&B22 -> Auteur!D33 | D22: =B22+1 -> 34 | E22: =$C$2&"!"&$C$3&D22 -> Auteur!D34 | F22: 36 | G22: =$C$2&"!"&$C$5&F22 -> Auteur!C36 | H22: =$C$2&"!"&$C$6&F22 -> Auteur!D36
A23: 3 | F23: =+F22+1 -> 37 | G23: =$C$2&"!"&$C$5&F23 -> Auteur!C37 | H23: =$C$2&"!"&$C$6&F23 -> Auteur!D37
A24: 3 | F24: =+F23+1 -> 38 | G24: =$C$2&"!"&$C$5&F24 -> Auteur!C38 | H24: =$C$2&"!"&$C$6&F24 -> Auteur!D38
A25: 3 | F25: =+F24+1 -> 39 | G25: =$C$2&"!"&$C$5&F25 -> Auteur!C39 | H25: =$C$2&"!"&$C$6&F25 -> Auteur!D39
A26: 3 | F26: =+F25+1 -> 40 | G26: =$C$2&"!"&$C$5&F26 -> Auteur!C40 | H26: =$C$2&"!"&$C$6&F26 -> Auteur!D40
A27: =A22+1 -> 4 | B27: 42 | C27: =$C$2&"!"&$C$3&B27 -> Auteur!D42 | D27: =B27+1 -> 43 | E27: =$C$2&"!"&$C$3&D27 -> Auteur!D43 | F27: 45 | G27: =$C$2&"!"&$C$5&F27 -> Auteur!C45 | H27: =$C$2&"!"&$C$6&F27 -> Auteur!D45
A28: 4 | F28: =+F27+1 -> 46 | G28: =$C$2&"!"&$C$5&F28 -> Auteur!C46 | H28: =$C$2&"!"&$C$6&F28 -> Auteur!D46
A29: 4 | F29: =+F28+1 -> 47 | G29: =$C$2&"!"&$C$5&F29 -> Auteur!C47 | H29: =$C$2&"!"&$C$6&F29 -> Auteur!D47
A30: 4 | F30: =+F29+1 -> 48 | G30: =$C$2&"!"&$C$5&F30 -> Auteur!C48 | H30: =$C$2&"!"&$C$6&F30 -> Auteur!D48
A31: 4 | F31: =+F30+1 -> 49 | G31: =$C$2&"!"&$C$5&F31 -> Auteur!C49 | H31: =$C$2&"!"&$C$6&F31 -> Auteur!D49
A32: =A27+1 -> 5 | B32: 51 | C32: =$C$2&"!"&$C$3&B32 -> Auteur!D51 | D32: =B32+1 -> 52 | E32: =$C$2&"!"&$C$3&D32 -> Auteur!D52 | F32: 54 | G32: =$C$2&"!"&$C$5&F32 -> Auteur!C54 | H32: =$C$2&"!"&$C$6&F32 -> Auteur!D54
A33: 5 | F33: =+F32+1 -> 55 | G33: =$C$2&"!"&$C$5&F33 -> Auteur!C55 | H33: =$C$2&"!"&$C$6&F33 -> Auteur!D55
A34: 5 | F34: =+F33+1 -> 56 | G34: =$C$2&"!"&$C$5&F34 -> Auteur!C56 | H34: =$C$2&"!"&$C$6&F34 -> Auteur!D56
A35: 5 | F35: =+F34+1 -> 57 | G35: =$C$2&"!"&$C$5&F35 -> Auteur!C57 | H35: =$C$2&"!"&$C$6&F35 -> Auteur!D57
A36: 5 | F36: =+F35+1 -> 58 | G36: =$C$2&"!"&$C$5&F36 -> Auteur!C58 | H36: =$C$2&"!"&$C$6&F36 -> Auteur!D58
A37: =A32+1 -> 6 | B37: 60 | C37: =$C$2&"!"&$C$3&B37 -> Auteur!D60 | D37: =B37+1 -> 61 | E37: =$C$2&"!"&$C$3&D37 -> Auteur!D61 | F37: 64 | G37: =$C$2&"!"&$C$5&F37 -> Auteur!C64 | H37: =$C$2&"!"&$C$6&F37 -> Auteur!D64
A38: 6 | F38: =+F37+1 -> 65 | G38: =$C$2&"!"&$C$5&F38 -> Auteur!C65 | H38: =$C$2&"!"&$C$6&F38 -> Auteur!D65
A39: 6 | F39: =+F38+1 -> 66 | G39: =$C$2&"!"&$C$5&F39 -> Auteur!C66 | H39: =$C$2&"!"&$C$6&F39 -> Auteur!D66
A40: 6 | F40: =+F39+1 -> 67 | G40: =$C$2&"!"&$C$5&F40 -> Auteur!C67 | H40: =$C$2&"!"&$C$6&F40 -> Auteur!D67
A41: 6 | F41: 68 | G41: =$C$2&"!"&$C$5&F41 -> Auteur!C68 | H41: =$C$2&"!"&$C$6&F41 -> Auteur!D68
...
